Workbook

Sheet Lead Tracker
A1: MOXIDENT — Dentist Outreach Tracker
A2: Last updated: March 27, 2026 | Total Leads: 77
A3: Dentist | B3: Practice | C3: Email | D3: Phone | E3: City | F3: State | G3: Email Sent | H3: Status | I3: Last Contact | J3: Next Follow-Up | K3: Days Since Contact | L3: Follow-Up Due? | M3: Response Notes
A4: Dr. Gan | B4: Genuine Smiles Family Dentistry | C4: jade@genuine-smiles.com | D4: +1 425-367-0303 | E4: Everett | F4: WA | G4: 03/27/2026 | H4: Sent — Awaiting Reply | I4: 03/27/2026 | J4: 03/30/2026 | K4: =IF(I4="","",TODAY()-I4) -> 0 | L4: =IF(J4="","",IF(TODAY()>=J4,"YES","No")) -> No
A5: Dr. Vuong | B5: All Smiles NW | C5: anthony.vuong@heartland.com | D5: +1 425-252-9333 | E5: Everett | F5: WA | G5: 03/27/2026 | H5: Sent — Awaiting Reply | I5: 03/27/2026 | J5: 03/30/2026 | K5: =IF(I5="","",TODAY()-I5) -> 0 | L5: =IF(J5="","",IF(TODAY()>=J5,"YES","No")) -> No
A6: Dr. Chen | B6: Pine Lake Family Dentistry | C6: drchen@pinelakefamilydentistry.com | E6: Sammamish | F6: WA | G6: 03/27/2026 | H6: Sent — Awaiting Reply | I6: 03/27/2026 | J6: 03/30/2026 | K6: =IF(I6="","",TODAY()-I6) -> 0 | L6: =IF(J6="","",IF(TODAY()>=J6,"YES","No")) -> No
A7: Dr. Nelson-Glickman | B7: Caron Nelson Glickman, DDS | C7: drcaron@great-smile.com | E7: Duvall | F7: WA | G7: 03/27/2026 | H7: Sent — Awaiting Reply | I7: 03/27/2026 | J7: 03/30/2026 | K7: =IF(I7="","",TODAY()-I7) -> 0 | L7: =IF(J7="","",IF(TODAY()>=J7,"YES","No")) -> No
A8: Dr. Wicklund | B8: WICKLUND DENTAL | C8: dr.wicklund@wicklunddental.com | E8: Bainbridge Island | F8: WA | G8: 03/27/2026 | H8: Sent — Awaiting Reply | I8: 03/27/2026 | J8: 03/30/2026 | K8: =IF(I8="","",TODAY()-I8) -> 0 | L8: =IF(J8="","",IF(TODAY()>=J8,"YES","No")) -> No
A9: Dr. Lightner | B9: Thomas Dentistry | C9: lightner@thomas-dentistry.com | D9: +1 425-821-2526 | E9: Kirkland | F9: WA | G9: 03/27/2026 | H9: Sent — Awaiting Reply | I9: 03/27/2026 | J9: 03/30/2026 | K9: =IF(I9="","",TODAY()-I9) -> 0 | L9: =IF(J9="","",IF(TODAY()>=J9,"YES","No")) -> No
A10: Dr. Kim | B10: Christy A. Kim, D.D.S., P.L.L.C. | C10: christykim@yourbellevuedentist.com | D10: +1 425-883-3800 | E10: Bellevue | F10: WA | G10: 03/27/2026 | H10: Sent — Awaiting Reply | I10: 03/27/2026 | J10: 03/30/2026 | K10: =IF(I10="","",TODAY()-I10) -> 0 | L10: =IF(J10="","",IF(TODAY()>=J10,"YES","No")) -> No
A11: Dr. Krumly | B11: Krumly Dental Care | C11: dr.krumly@krumlydentalcare.com | D11: +1 206-557-4522 | E11: Seattle | F11: WA | G11: 03/27/2026 | H11: Sent — Awaiting Reply | I11: 03/27/2026 | J11: 03/30/2026 | K11: =IF(I11="","",TODAY()-I11) -> 0 | L11: =IF(J11="","",IF(TODAY()>=J11,"YES","No")) -> No
A12: Dr. Woo | B12: W Dentistry | C12: drkariwoo@w-dentistry.com | D12: +1 586-480-2256 | E12: Issaquah | F12: WA | G12: 03/27/2026 | H12: Sent — Awaiting Reply | I12: 03/27/2026 | J12: 03/30/2026 | K12: =IF(I12="","",TODAY()-I12) -> 0 | L12: =IF(J12="","",IF(TODAY()>=J12,"YES","No")) -> No
A13: Dr. Kelley | B13: Kelley Family Dentistry | C13: matthew@kelleyfamilydentistry.com | D13: +1 425-771-3505 | E13: Mountlake Terrace | F13: WA | G13: 03/27/2026 | H13: Sent — Awaiting Reply | I13: 03/27/2026 | J13: 03/30/2026 | K13: =IF(I13="","",TODAY()-I13) -> 0 | L13: =IF(J13="","",IF(TODAY()>=J13,"YES","No")) -> No
A14: Dr. Bauer | B14: Family Dental Care of Bellevue | C14: dr.bauer@familydentalcareofbellevue.com | D14: +1 425-643-5778 | E14: Bellevue | F14: WA | G14: 03/27/2026 | H14: Sent — Awaiting Reply | I14: 03/27/2026 | J14: 03/30/2026 | K14: =IF(I14="","",TODAY()-I14) -> 0 | L14: =IF(J14="","",IF(TODAY()>=J14,"YES","No")) -> No
A15: Dr. Wagar | B15: Benson Hill Smiles | C15: drwagar@bensonhillsmiles.com | E15: Renton | F15: WA | G15: 03/27/2026 | H15: Sent — Awaiting Reply | I15: 03/27/2026 | J15: 03/30/2026 | K15: =IF(I15="","",TODAY()-I15) -> 0 | L15: =IF(J15="","",IF(TODAY()>=J15,"YES","No")) -> No
A16: Dr. Hwang | B16: Creo Dentistry | C16: dan@creodentistry.com | D16: +1 360-502-7217 | E16: Marysville | F16: WA | G16: 03/27/2026 | H16: Sent — Awaiting Reply | I16: 03/27/2026 | J16: 03/30/2026 | K16: =IF(I16="","",TODAY()-I16) -> 0 | L16: =IF(J16="","",IF(TODAY()>=J16,"YES","No")) -> No
A17: Dr. Caldier | B17: Golden Age Dentistry | C17: michelle@michellecaldier.com | E17: Riverside | F17: WA | G17: 03/27/2026 | H17: Sent — Awaiting Reply | I17: 03/27/2026 | J17: 03/30/2026 | K17: =IF(I17="","",TODAY()-I17) -> 0 | L17: =IF(J17="","",IF(TODAY()>=J17,"YES","No")) -> No
A18: Dr. Ament | B18: Michelle J. Ament DDS Bothell Family Dentistry | C18: drament@bothellfamilydentistry.com | D18: +1 425-486-2787 | E18: Bothell | F18: WA | G18: 03/27/2026 | H18: Sent — Awaiting Reply | I18: 03/27/2026 | J18: 03/30/2026 | K18: =IF(I18="","",TODAY()-I18) -> 0 | L18: =IF(J18="","",IF(TODAY()>=J18,"YES","No")) -> No
A19: Dr. Furman | B19: All Smiles Family Dentistry | C19: ilona@asfamilydentistry.com | D19: +1 931-553-6959 | E19: Clarksville | F19: WA | G19: 03/27/2026 | H19: Sent — Awaiting Reply | I19: 03/27/2026 | J19: 03/30/2026 | K19: =IF(I19="","",TODAY()-I19) -> 0 | L19: =IF(J19="","",IF(TODAY()>=J19,"YES","No")) -> No
A20: Dr. Kitts | B20: Soundview Family Dental | C20: yana@soundviewfamilydental.com | D20: +1 425-563-6360 | E20: Edmonds | F20: WA | G20: 03/27/2026 | H20: Sent — Awaiting Reply | I20: 03/27/2026 | J20: 03/30/2026 | K20: =IF(I20="","",TODAY()-I20) -> 0 | L20: =IF(J20="","",IF(TODAY()>=J20,"YES","No")) -> No
A21: Dr. Gerlach | B21: Bellevue Pediatric Dentistry | C21: nolan@kidsdentistofbellevue.com | D21: +1 425-614-3777 | E21: Bellevue | F21: WA | G21: 03/27/2026 | H21: Sent — Awaiting Reply | I21: 03/27/2026 | J21: 03/30/2026 | K21: =IF(I21="","",TODAY()-I21) -> 0 | L21: =IF(J21="","",IF(TODAY()>=J21,"YES","No")) -> No
A22: Dr. Yoon | B22: Bothell Everett Kids Dentistry | C22: tae.yoon@bekidsdentistry.com | D22: +1 425-286-2078 | E22: Bothell | F22: WA | G22: 03/27/2026 | H22: Sent — Awaiting Reply | I22: 03/27/2026 | J22: 03/30/2026 | K22: =IF(I22="","",TODAY()-I22) -> 0 | L22: =IF(J22="","",IF(TODAY()>=J22,"YES","No")) -> No
A23: Dr. Posthuma | B23: The Tooth Ferry | C23: kidsonly@toothferrydentistry.com | E23: Friday Harbor | F23: WA | G23: 03/27/2026 | H23: Sent — Awaiting Reply | I23: 03/27/2026 | J23: 03/30/2026 | K23: =IF(I23="","",TODAY()-I23) -> 0 | L23: =IF(J23="","",IF(TODAY()>=J23,"YES","No")) -> No
A24: Dr. Riley | B24: Northwest Dental Medicine | C24: drriley@nwdentalmed.com | D24: +1 253-845-9507 | E24: Puyallup | F24: WA | G24: 03/27/2026 | H24: Sent — Awaiting Reply | I24: 03/27/2026 | J24: 03/30/2026 | K24: =IF(I24="","",TODAY()-I24) -> 0 | L24: =IF(J24="","",IF(TODAY()>=J24,"YES","No")) -> No
A25: Dr. Minahan | B25: Minahan Dental | C25: dral@minahandental.com | E25: Seattle | F25: WA | G25: 03/27/2026 | H25: Sent — Awaiting Reply | I25: 03/27/2026 | J25: 03/30/2026 | K25: =IF(I25="","",TODAY()-I25) -> 0 | L25: =IF(J25="","",IF(TODAY()>=J25,"YES","No")) -> No
A26: Dr. Rasmussen | B26: LEIF RASMUSSEN, DDS, PLLC | C26: lrasmussen@vashondental.com | E26: Vashon | F26: WA | G26: 03/27/2026 | H26: Sent — Awaiting Reply | I26: 03/27/2026 | J26: 03/30/2026 | K26: =IF(I26="","",TODAY()-I26) -> 0 | L26: =IF(J26="","",IF(TODAY()>=J26,"YES","No")) -> No
A27: Dr. Seuk | B27: Lake Union Family Dental | C27: gseuk@lakeunionfamilydental.com | E27: Seattle | F27: WA | G27: 03/27/2026 | H27: Sent — Awaiting Reply | I27: 03/27/2026 | J27: 03/30/2026 | K27: =IF(I27="","",TODAY()-I27) -> 0 | L27: =IF(J27="","",IF(TODAY()>=J27,"YES","No")) -> No
A28: Dr. Ahn | B28: Federal Way Modern Dentistry | C28: jahn@federalwaymoderndentistry.com | D28: +1 253-432-8942 | E28: Federal Way | F28: WA | G28: 03/27/2026 | H28: Sent — Awaiting Reply | I28: 03/27/2026 | J28: 03/30/2026 | K28: =IF(I28="","",TODAY()-I28) -> 0 | L28: =IF(J28="","",IF(TODAY()>=J28,"YES","No")) -> No
A29: Dr. Lebeau | B29: Lebeau Dental | C29: dene@lebeaudental.com | D29: '+1 425-251-3535 | E29: Renton | F29: WA | G29: 03/27/2026 | H29: Sent — Awaiting Reply | I29: 03/27/2026 | J29: 03/30/2026 | K29: =IF(I29="","",TODAY()-I29) -> 0 | L29: =IF(J29="","",IF(TODAY()>=J29,"YES","No")) -> No
A30: Dr. Letwin | B30: Seattle Special Care Dentistry | C30: nletwin@sscdentistry.com | D30: '+1 206-524-1600 | E30: Seattle | F30: WA | G30: 03/27/2026 | H30: Sent — Awaiting Reply | I30: 03/27/2026 | J30: 03/30/2026 | K30: =IF(I30="","",TODAY()-I30) -> 0 | L30: =IF(J30="","",IF(TODAY()>=J30,"YES","No")) -> No
A31: Dr. Goyer | B31: Inland Family Dentistry | C31: ngoyer@ifdww.com | E31: Kennewick | F31: WA | G31: 03/27/2026 | H31: Sent — Awaiting Reply | I31: 03/27/2026 | J31: 03/30/2026 | K31: =IF(I31="","",TODAY()-I31) -> 0 | L31: =IF(J31="","",IF(TODAY()>=J31,"YES","No")) -> No
A32: Dr. Sulaiman | B32: Pacific Prosthodontics | C32: frankie@pacificprosthodontics.com | D32: '+1 206-522-5300 | E32: Seattle | F32: WA | G32: 03/27/2026 | H32: Sent — Awaiting Reply | I32: 03/27/2026 | J32: 03/30/2026 | K32: =IF(I32="","",TODAY()-I32) -> 0 | L32: =IF(J32="","",IF(TODAY()>=J32,"YES","No")) -> No
A33: Dr. Trieu | B33: North Everett Family Dental | C33: ktrieu@familydentistry.com | E33: Seattle | F33: WA | G33: 03/27/2026 | H33: Sent — Awaiting Reply | I33: 03/27/2026 | J33: 03/30/2026 | K33: =IF(I33="","",TODAY()-I33) -> 0 | L33: =IF(J33="","",IF(TODAY()>=J33,"YES","No")) -> No
A34: Dr. Hou | B34: Sound Orthodontics | C34: drjack@soundorthodontics.com | D34: '+1 206-935-2414 | E34: Seattle | F34: WA | G34: 03/27/2026 | H34: Sent — Awaiting Reply | I34: 03/27/2026 | J34: 03/30/2026 | K34: =IF(I34="","",TODAY()-I34) -> 0 | L34: =IF(J34="","",IF(TODAY()>=J34,"YES","No")) -> No
A35: Dr. Hasegawa | B35: Hasegawa Family & Esthetic Dentistry | C35: p.hasegawa@hasegawadds.com | E35: Seattle | F35: WA | G35: 03/27/2026 | H35: Sent — Awaiting Reply | I35: 03/27/2026 | J35: 03/30/2026 | K35: =IF(I35="","",TODAY()-I35) -> 0 | L35: =IF(J35="","",IF(TODAY()>=J35,"YES","No")) -> No
A36: Dr. Ness | B36: Ness Family Dentistry | C36: shane@shanenessdds.com | E36: Redmond | F36: WA | G36: 03/27/2026 | H36: Sent — Awaiting Reply | I36: 03/27/2026 | J36: 03/30/2026 | K36: =IF(I36="","",TODAY()-I36) -> 0 | L36: =IF(J36="","",IF(TODAY()>=J36,"YES","No")) -> No
A37: Dr. Magnuson | B37: Premier Sleep | C37: drcarrie@premiersleepassociates.com | D37: '+1 360-979-1537 | E37: Bellevue | F37: WA | G37: 03/27/2026 | H37: Sent — Awaiting Reply | I37: 03/27/2026 | J37: 03/30/2026 | K37: =IF(I37="","",TODAY()-I37) -> 0 | L37: =IF(J37="","",IF(TODAY()>=J37,"YES","No")) -> No
A38: Dr. Bickel | B38: Redmond Art of Dentistry | C38: dbickel@myredmonddentist.com | D38: '+1 425-883-1331 | E38: Redmond | F38: WA | G38: 03/27/2026 | H38: Sent — Awaiting Reply | I38: 03/27/2026 | J38: 03/30/2026 | K38: =IF(I38="","",TODAY()-I38) -> 0 | L38: =IF(J38="","",IF(TODAY()>=J38,"YES","No")) -> No
A39: Dr. Becker | B39: Kids On 1st Dentistry | C39: mbecker@kidson1st.com | D39: '+1 253-517-7780 | E39: Seattle | F39: WA | G39: 03/27/2026 | H39: Sent — Awaiting Reply | I39: 03/27/2026 | J39: 03/30/2026 | K39: =IF(I39="","",TODAY()-I39) -> 0 | L39: =IF(J39="","",IF(TODAY()>=J39,"YES","No")) -> No
A40: Dr. Sanders | B40: Sanders Family Dental | C40: dr.sanders@sandersfamily.dental | E40: Spokane | F40: WA | G40: 03/27/2026 | H40: Sent — Awaiting Reply | I40: 03/27/2026 | J40: 03/30/2026 | K40: =IF(I40="","",TODAY()-I40) -> 0 | L40: =IF(J40="","",IF(TODAY()>=J40,"YES","No")) -> No
...

Sheet Dashboard
A1: MOXIDENT — Outreach Dashboard
A3: Total Leads | B3: Awaiting Reply | C3: Interested | D3: Meetings Set | E3: Onboarded | F3: Follow-Ups Due
A4: =COUNTA('Lead Tracker'!A4:A80) -> 77 | B4: =COUNTIF('Lead Tracker'!H4:H80,"Sent — Awaiting Reply")+COUNTIF('Lead Tracker'!H4:H80,"Follow-Up Sent") -> 77 | C4: =COUNTIF('Lead Tracker'!H4:H80,"Replied — Interested") -> 0 | D4: =COUNTIF('Lead Tracker'!H4:H80,"Meeting Scheduled") -> 0 | E4: =COUNTIF('Lead Tracker'!H4:H80,"Onboarded") -> 0 | F4: =COUNTIF('Lead Tracker'!L4:L80,"YES") -> 0
A7: Pipeline Breakdown
A8: Status | B8: Count | C8: % of Total
A9: Sent — Awaiting Reply | B9: =COUNTIF('Lead Tracker'!H4:H80,A9) -> 77 | C9: =IF(B9=0,"-",B9/COUNTA('Lead Tracker'!A4:A80)) -> 1
A10: Follow-Up Sent | B10: =COUNTIF('Lead Tracker'!H4:H80,A10) -> 0 | C10: =IF(B10=0,"-",B10/COUNTA('Lead Tracker'!A4:A80)) -> -
A11: Replied — Interested | B11: =COUNTIF('Lead Tracker'!H4:H80,A11) -> 0 | C11: =IF(B11=0,"-",B11/COUNTA('Lead Tracker'!A4:A80)) -> -
A12: Replied — Not Interested | B12: =COUNTIF('Lead Tracker'!H4:H80,A12) -> 0 | C12: =IF(B12=0,"-",B12/COUNTA('Lead Tracker'!A4:A80)) -> -
A13: Meeting Scheduled | B13: =COUNTIF('Lead Tracker'!H4:H80,A13) -> 0 | C13: =IF(B13=0,"-",B13/COUNTA('Lead Tracker'!A4:A80)) -> -
A14: Onboarded | B14: =COUNTIF('Lead Tracker'!H4:H80,A14) -> 0 | C14: =IF(B14=0,"-",B14/COUNTA('Lead Tracker'!A4:A80)) -> -
A15: No Response | B15: =COUNTIF('Lead Tracker'!H4:H80,A15) -> 0 | C15: =IF(B15=0,"-",B15/COUNTA('Lead Tracker'!A4:A80)) -> -
A16: Bounced | B16: =COUNTIF('Lead Tracker'!H4:H80,A16) -> 0 | C16: =IF(B16=0,"-",B16/COUNTA('Lead Tracker'!A4:A80)) -> -
A18: Response Rate | B18: =COUNTIFS('Lead Tracker'!H4:H80,"<>Sent — Awaiting Reply",'Lead Tracker'!H4:H80,"<>Follow-Up Sent",'Lead Tracker'!H4:H80,"<>No Response",'Lead Tracker'!H4:H80,"<>Bounced",'Lead Tracker'!H4:H80,"<>") -> 0 | C18: =IF(B18=0,"-",B18/COUNTA('Lead Tracker'!A4:A80)) -> -

Sheet Follow-Up Cadence
A1: Follow-Up Cadence Guide
A3: Touchpoint | B3: Timing | C3: Channel | D3: Action
A4: 1st Email | B4: Day 0 | C4: Email | D4: Send initial outreach (done via drafts)
A5: 2nd Email | B5: Day 3 | C5: Email | D5: Gentle follow-up — reference first email
A6: 3rd Email | B6: Day 7 | C6: Email | D6: Add value — share a quick stat or insight
A7: Phone Call | B7: Day 10 | C7: Phone | D7: Quick call — introduce yourself, reference emails
A8: 4th Email | B8: Day 14 | C8: Email | D8: Final follow-up — leave door open
A9: Mark Cold | B9: Day 21 | C9: — | D9: If no response, mark as No Response
A11: Follow-Up Email Templates
A13: Follow-Up #1 (Day 3) | B13: Subject: re: quick question Hi Dr. [Name], Just circling back — I had another emergency patient situation yesterday and it reminded me to follow up. Would your office be open to receiving same-day emergency referrals when you have availability? No cost unless the patient shows. Allen Hafezipour Founder, Moxident (425) 403-6723
A21: Follow-Up #2 (Day 7) | B21: Subject: quick stat for your area Hi Dr. [Name], On average, we're seeing 3-4 emergency patients per week in your area who can't find same-day care. I'm building a small network of clinics to route these patients to. Would you be open to a quick conversation about how it works? moxident.com/dentist/survey Allen Hafezipour Founder, Moxident (425) 403-6723
A29: Final Follow-Up (Day 14) | B29: Subject: last note from me Hi Dr. [Name], I know you're busy so I'll keep this short — I won't follow up again, but if you ever want to receive same-day emergency patient referrals, the door is always open. moxident.com/dentist/survey Allen Hafezipour Founder, Moxident (425) 403-6723
